<mujoco>
  <!-- Simulator options -->
  <option timestep="0.002" iterations="1" ls_iterations="5" integrator="implicitfast"/>

  <!-- Defaults -->
  <default>
    <!-- No contact, everything is grey-->
    <geom rgba="0.5 0.5 0.5 1" conaffinity="0"/>

    <!-- Note that joint damping has a big impact on sim stability, esp. with
         the tendon -->
    <joint damping="1e-4"/>
  </default>

  <!-- The robot -->
  <worldbody>
    <body name="base" pos="0 0 0.3">
      <geom type="box" size="0.2 0.2 0.05" />
      <body name="imu1" pos="0.05 0.0 0.05">
        <geom type="box" size=".022 .024 0.003" rgba="1 0 0 1" />
        <site name="imu1_site" />
      </body>

      <!-- The slew/yaw joint rotates the crane. -->
      <body name="trunk" pos="0 0 0.1" quat="0.707 0 0 0.707">
        <joint name="slew" type="hinge" axis="0 0 1" pos="0 0 -.075" />
        <geom type="cylinder" size=".025 .05" />

        <!-- The luff/pitch joint moves the boom up and down. -->
        <body pos="0 0 .1">
          <geom type="box" size=".05 .05 .05" />
          <body name="boom" pos="1.1 0 .12">
            <joint name="luff" type="hinge" axis="0 -1 0" pos="-1.1 0 -.12" range="0 60" />

            <!-- Connecter pieces between the boom and the base-->
            <body pos="-1.1 0 -0.04">
              <geom type="box" size=".025 .055 .0025" />
              <body pos="0 -.0525 -.05375">
                <geom type="box" size=".025 .0025 .05125" />
                <body name="imu2" pos="0.0 -0.0055 0.0">
                  <geom type="box" size=".022 .003 0.024" rgba="1 0 0 1" />
                  <site name="imu2_site" />
                </body>
              </body>
              <body pos="0 .0525 -.05375">
                <geom type="box" size=".025 .0025 .05125" />
              </body>
            </body>

            <!-- The boom itself -->
            <!-- Note that we use a lower density (1000 is default) to reduce
                 the mass ratios in the sim, which makes the sim more stable.
            -->
            <geom type="box" density="100" size="1.22 .0375 .0375" />
            <body name="imu3" pos="0 -0.0405 0">
              <geom type="box" size=".020 .003 0.023" rgba="1 0 0 1" />
              <site name="imu3_site" />
            </body>

            <!-- The site for attaching the cable -->
            <site name="boom_end" pos="1.22 0 -0.0375" />

          </body>
        </body>
      </body>
    </body>

    <!-- The payload -->
    <body name="payload" pos="0.0 2.32 0.3">
      <joint type="free" />
      <geom type="capsule" size=".01 0.15" rgba="0.99 0.99 0.99 1.0" />

      <!-- Site to attach the top of the payload -->
      <site name="payload_top" pos="0 0 0.15" />

      <!-- We assume we can measure the position of the end of the payload -->
      <site name="payload_end" pos="0 0 -0.15" />
    </body>

    <!-- Target payload position-->
    <body name="target" pos="0.05 2.0 0.3" mocap="true">
      <site name="target" />
      <geom type="sphere" size="0.02" rgba="0 1 0 1" />
    </body>
  </worldbody>

  <!-- The cable holding the payload -->
  <tendon>
    <spatial name="cable" damping="0.0">
      <site site="boom_end"/>
      <site site="payload_top"/>
    </spatial>
  </tendon>

  <!-- Sensors -->
  <sensor>
    <!-- IMUs -->
    <gyro name="imu1_gyro" site="imu1_site" />
    <accelerometer name="imu1_accel" site="imu1_site" />
    <gyro name="imu2_gyro" site="imu2_site" />
    <accelerometer name="imu2_accel" site="imu2_site" />
    <gyro name="imu3_gyro" site="imu3_site" />
    <accelerometer name="imu3_accel" site="imu3_site" />

    <!-- Payload position and velocity relative to the target -->
    <framepos name="payload_pos" objtype="site" objname="payload_end" reftype="site" refname="target"/>
    <framelinvel name="payload_vel" objtype="site" objname="payload_end" reftype="site" refname="target"/>
  </sensor>

  <actuator>
    <position name="slew" joint="slew" ctrlrange="-1 1" kp="10" dampratio="1.0" />
    <position name="luff" joint="luff" ctrlrange="0 1" kp="100" dampratio="1.0" />
    <position name="hoist" tendon="cable" kp="10" dampratio="1.0" forcerange="-10 0" ctrlrange="0.05 2.0"/>
  </actuator>
</mujoco>
