<mujoco model="g1">
  <compiler angle="radian" meshdir="assets" autolimits="true"/>

  <option timestep="0.03" iterations="1" ls_iterations="5">
    <flag eulerdamp="disable"/>
  </option>

  <custom>
    <numeric data="5" name="max_contact_points" />
    <numeric data="5" name="max_geom_pairs" />
  </custom>

  <default>
    <geom condim="3"/>
    <default class="g1">
      <site rgba="1 0 0 1" size="0.01" group="5"/>
      <joint damping="0.0" armature="1.0" frictionloss="0.0"/>
      <velocity kv="0.01" ctrllimited="true" ctrlrange="-5.0 5.0"/>
      <default class="arm_joint">
        <position kp="10" forcerange="-20 20"/>
      </default>
      <default class="hip_joint">
        <position kp="40" dampratio="0.2" forcerange="-88 88"/>
      </default>
      <default class="knee_joint">
        <position kp="40" forcerange="-139 139"/>
      </default>
      <default class="ankle_joint">
        <position kp="30" forcerange="-40 40"/>
      </default>
      <default class="torso_joint">
        <position kp="20" forcerange="-88 88"/>
      </default>
      <default class="visual">
        <geom group="2" type="mesh" contype="0" conaffinity="0" density="0" material="metallic"/>
      </default>
      <default class="col">
        <geom group="3" type="capsule"/>
        <default class="foot_collision">
          <geom quat="0.707107 0.707107 0 0" type="capsule" size="0.02 0.02"/>
        </default>
        <default class="shin_collision">
          <geom pos="0.007 0.005 -0.18" size="0.03 0.1"/>
        </default>
        <default class="knee_collision">
          <geom pos="-0.08 0.0 -0.18" type="sphere" size="0.05"/>
        </default>
        <default class="thigh_collision">
          <geom pos="-0.02 0.0 0.0" size="0.05 0.12"/>
        </default>
        <default class="pelvis_collision">
          <geom pos="0.0 0.0 0.18" size="0.06 0.27"/>
        </default>
        <default class="torso_collision">
          <geom pos="0.0 0.0 0.0" size="0.05 0.1"/>
        </default>
        <default class="shoulder_collision">
          <geom pos="-0.004 0.006 -0.09" size="0.03 0.09" />
        </default>
        <default class="forearm_collision">
          <geom pos="0.03 0 0" quat="0.707107 0 0.707107 0 " size="0.03 0.07" />
        </default>
        <default class="hand_collision">
          <geom pos="0.15 0 0" type="sphere" size="0.03"/>
        </default>
      </default>
    </default>
  </default>

  <asset>
    <material name="metallic" rgba="0.7 0.7 0.7 1"/>
    <material name="black" rgba="0.2 0.2 0.2 1"/>

    <mesh file="pelvis.STL"/>
    <mesh file="pelvis_contour_link.STL"/>
    <mesh file="left_hip_pitch_link.STL"/>
    <mesh file="left_hip_roll_link.STL"/>
    <mesh file="left_hip_yaw_link.STL"/>
    <mesh file="left_knee_link.STL"/>
    <mesh file="left_ankle_pitch_link.STL"/>
    <mesh file="left_ankle_roll_link.STL"/>
    <mesh file="right_hip_pitch_link.STL"/>
    <mesh file="right_hip_roll_link.STL"/>
    <mesh file="right_hip_yaw_link.STL"/>
    <mesh file="right_knee_link.STL"/>
    <mesh file="right_ankle_pitch_link.STL"/>
    <mesh file="right_ankle_roll_link.STL"/>
    <mesh file="torso_link.STL"/>
    <mesh file="head_link.STL"/>
    <mesh file="left_shoulder_pitch_link.STL"/>
    <mesh file="left_shoulder_roll_link.STL"/>
    <mesh file="left_shoulder_yaw_link.STL"/>
    <mesh file="left_elbow_pitch_link.STL"/>
    <mesh file="left_elbow_roll_link.STL"/>
    <mesh file="right_shoulder_pitch_link.STL"/>
    <mesh file="right_shoulder_roll_link.STL"/>
    <mesh file="right_shoulder_yaw_link.STL"/>
    <mesh file="right_elbow_pitch_link.STL"/>
    <mesh file="right_elbow_roll_link.STL"/>
    <mesh file="logo_link.STL"/>
    <mesh file="left_palm_link.STL"/>
    <mesh file="left_zero_link.STL"/>
    <mesh file="left_one_link.STL"/>
    <mesh file="left_two_link.STL"/>
    <mesh file="left_three_link.STL"/>
    <mesh file="left_four_link.STL"/>
    <mesh file="left_five_link.STL"/>
    <mesh file="left_six_link.STL"/>
    <mesh file="right_palm_link.STL"/>
    <mesh file="right_zero_link.STL"/>
    <mesh file="right_one_link.STL"/>
    <mesh file="right_two_link.STL"/>
    <mesh file="right_three_link.STL"/>
    <mesh file="right_four_link.STL"/>
    <mesh file="right_five_link.STL"/>
    <mesh file="right_six_link.STL"/>
  </asset>

  <worldbody>
    <light name="spotlight" mode="targetbodycom" target="pelvis" pos="0 -6 4" cutoff="30"/>
    <body name="pelvis" pos="0 0 0.755" childclass="g1">
      <inertial pos="0 0 -0.07605" quat="1 0 -0.000405289 0" mass="2.86" diaginertia="0.0079143 0.0069837 0.0059404"/>
      <freejoint name="floating_base_joint"/>
      <light name="tracking" mode="trackcom" pos="0 0 2"/>
      <geom type="mesh" class="visual" mesh="pelvis"/>
      <geom class="pelvis_collision" />
      <geom type="mesh" class="visual" material="black" mesh="pelvis_contour_link"/>
      <body name="left_hip_pitch_link" pos="0 0.06445 -0.1027" quat="0.984807 0 -0.17365 0">
        <inertial pos="0.001962 0.049392 -0.000941" quat="0.420735 0.907025 -0.0155675 -0.00670646" mass="1.299"
          diaginertia="0.00138785 0.000955478 0.00086947"/>
        <joint name="left_hip_pitch_joint" axis="0 1 0" range="-2.35 3.05"/>
        <geom type="mesh" class="visual" material="black" mesh="left_hip_pitch_link"/>
        <body name="left_hip_roll_link" pos="0 0.0523 0">
          <inertial pos="0.024757 -0.001036 -0.086323" quat="0.977498 -0.00692636 0.210181 0.0165269" mass="1.446"
            diaginertia="0.00244106 0.00230425 0.00142899"/>
          <joint name="left_hip_roll_joint" axis="1 0 0" range="-0.26 2.53"/>
          <geom type="mesh" class="visual" mesh="left_hip_roll_link"/>
          <body name="left_hip_yaw_link" pos="0.01966 -0.0012139 -0.1241">
            <inertial pos="-0.053554 -0.011477 -0.14067" quat="0.645099 0.15885 0.202109 0.71956" mass="2.052"
              diaginertia="0.0114475 0.0107868 0.00214501"/>
            <joint name="left_hip_yaw_joint" axis="0 0 1" range="-2.75 2.75"/>
            <geom type="mesh" class="visual" mesh="left_hip_yaw_link"/>
            <geom class="thigh_collision" />
            <geom class="knee_collision" />
            <body name="left_knee_link" pos="-0.078292 -0.0017335 -0.177225" quat="0.967714 0 0.252052 0">
              <inertial pos="0.005505 0.006534 -0.116629" quat="0.799234 -0.0128894 0.0354278 0.599836" mass="2.252"
                diaginertia="0.0127418 0.0124382 0.00192524"/>
              <joint name="left_knee_joint" axis="0 1 0" range="-0.33489 2.5449"/>
              <geom type="mesh" class="visual" mesh="left_knee_link"/>
              <geom class="shin_collision" />
              <body name="left_ankle_pitch_link" pos="0 0.0040687 -0.30007" quat="0.99678 0 -0.0801788 0">
                <inertial pos="-0.007269 0 0.011137" quat="0.603053 0.369225 0.369225 0.603053" mass="0.074"
                  diaginertia="1.89e-05 1.40805e-05 6.9195e-06"/>
                <joint name="left_ankle_pitch_joint" axis="0 1 0" range="-0.68 0.73"/>
                <geom type="mesh" class="visual" mesh="left_ankle_pitch_link"/>
                <body name="left_ankle_roll_link" pos="0 0 -0.017558">
                  <inertial pos="0.024762 2e-05 -0.012526" quat="0.000771333 0.734476 0.000921291 0.678634" mass="0.391"
                    diaginertia="0.00110394 0.0010657 0.000149255"/>
                  <joint name="left_ankle_roll_joint" axis="1 0 0" range="-0.2618 0.2618"/>
                  <geom type="mesh" class="visual" material="black" mesh="left_ankle_roll_link"/>
                  <geom pos="-0.04 0.0 -0.015" class="foot_collision" />
                  <geom pos="0.11 0.0 -0.015" class="foot_collision" />
                  <site name="left_heel" pos="-0.04 0.0 -0.015"/>
                  <site name="left_toe" pos="0.11 0.0 -0.015"/>
                </body>
              </body>
            </body>
          </body>
        </body>
      </body>
      <body name="right_hip_pitch_link" pos="0 -0.06445 -0.1027" quat="0.984807 0 -0.17365 0">
        <inertial pos="0.001962 -0.049392 -0.000941" quat="0.907025 0.420735 0.00670646 0.0155675" mass="1.299"
          diaginertia="0.00138785 0.000955478 0.00086947"/>
        <joint name="right_hip_pitch_joint" axis="0 1 0" range="-2.35 3.05"/>
        <geom type="mesh" class="visual" material="black" mesh="right_hip_pitch_link"/>
        <body name="right_hip_roll_link" pos="0 -0.0523 0">
          <inertial pos="0.024757 0.001036 -0.086323" quat="0.977498 0.00692636 0.210181 -0.0165269" mass="1.446"
            diaginertia="0.00244106 0.00230425 0.00142899"/>
          <joint name="right_hip_roll_joint" axis="1 0 0" range="-2.53 0.26"/>
          <geom type="mesh" class="visual" mesh="right_hip_roll_link"/>
          <body name="right_hip_yaw_link" pos="0.01966 0.0012139 -0.1241">
            <inertial pos="-0.053554 0.011477 -0.14067" quat="0.71956 0.202109 0.15885 0.645099" mass="2.052"
              diaginertia="0.0114475 0.0107868 0.00214501"/>
            <joint name="right_hip_yaw_joint" axis="0 0 1" range="-2.75 2.75"/>
            <geom type="mesh" class="visual" mesh="right_hip_yaw_link"/>
            <geom class="thigh_collision" />
            <geom class="knee_collision" />
            <body name="right_knee_link" pos="-0.078292 0.0017335 -0.177225" quat="0.967714 0 0.252052 0">
              <inertial pos="0.005505 -0.006534 -0.116629" quat="0.599836 0.0354278 -0.0128894 0.799234" mass="2.252"
                diaginertia="0.0127418 0.0124382 0.00192524"/>
              <joint name="right_knee_joint" axis="0 1 0" range="-0.33489 2.5449"/>
              <geom type="mesh" class="visual" mesh="right_knee_link"/>
              <geom class="shin_collision" />
              <body name="right_ankle_pitch_link" pos="0 -0.0040687 -0.30007" quat="0.99678 0 -0.0801788 0">
                <inertial pos="-0.007269 0 0.011137" quat="0.603053 0.369225 0.369225 0.603053" mass="0.074"
                  diaginertia="1.89e-05 1.40805e-05 6.9195e-06"/>
                <joint name="right_ankle_pitch_joint" axis="0 1 0" range="-0.68 0.73"/>
                <geom type="mesh" class="visual" mesh="right_ankle_pitch_link"/>
                <body name="right_ankle_roll_link" pos="0 0 -0.017558">
                  <inertial pos="0.024762 -2e-05 -0.012526" quat="-0.000771333 0.734476 -0.000921291 0.678634"
                    mass="0.391" diaginertia="0.00110394 0.0010657 0.000149255"/>
                  <joint name="right_ankle_roll_joint" axis="1 0 0" range="-0.2618 0.2618"/>
                  <geom type="mesh" class="visual" material="black" mesh="right_ankle_roll_link"/>
                  <geom pos="-0.04 0.0 -0.015" class="foot_collision" />
                  <geom pos="0.11 0.0 -0.015" class="foot_collision" />
                  <site name="right_heel" pos="-0.04 0.0 -0.015"/>
                  <site name="right_toe" pos="0.11 0.0 -0.015"/>
                </body>
              </body>
            </body>
          </body>
        </body>
      </body>
      <body name="torso_link">
        <inertial pos="0.00187791 0.00229457 0.208747" quat="0.999957 0.00624375 -0.00636707 -0.0026338" mass="7.52036"
          diaginertia="0.12848 0.111753 0.0350394"/>
        <site name="imu" pos="-0.04233868314 0.00166 0.152067"/>
        <site name="head" pos="0 0 0.5"/>
        <joint name="torso_joint" axis="0 0 1" range="-2.618 2.618"/>
        <geom type="mesh" class="visual" mesh="torso_link"/>
        <geom type="mesh" class="visual" material="black" mesh="head_link"/>
        <geom type="mesh" class="visual" material="black" mesh="logo_link"/>
        <geom class="torso_collision" pos="0.0 0.06 0.18" />
        <geom class="torso_collision" pos="0.0 -0.06 0.18" />
        <body name="left_shoulder_pitch_link" pos="-0.0025 0.10396 0.25928" quat="0.990268 0.139172 0 0">
          <inertial pos="-0.001431 0.048811 0.001304" quat="0.786417 0.588396 -0.180543 0.0523639" mass="0.713"
            diaginertia="0.000466421 0.000440181 0.000410999"/>
          <joint name="left_shoulder_pitch_joint" axis="0 1 0" range="-2.9671 2.7925"/>
          <geom type="mesh" class="visual" mesh="left_shoulder_pitch_link"/>
          <body name="left_shoulder_roll_link" pos="0 0.052 0" quat="0.990268 -0.139172 0 0">
            <inertial pos="-0.003415 0.006955 -0.064598" quat="0.70683 0.0105364 0.00575207 0.707282" mass="0.642"
              diaginertia="0.000683514 0.000616029 0.000372857"/>
            <joint name="left_shoulder_roll_joint" axis="1 0 0" range="-1.5882 2.2515"/>
            <geom type="mesh" class="visual" mesh="left_shoulder_roll_link"/>
            <geom class="shoulder_collision" />
            <body name="left_shoulder_yaw_link" pos="-0.00354 0.0062424 -0.1032">
              <inertial pos="0.000375 -0.00444 -0.072374" quat="0.903834 -0.0374183 0.00985482 0.42613" mass="0.713"
                diaginertia="0.000977874 0.000964661 0.000379065"/>
              <joint name="left_shoulder_yaw_joint" axis="0 0 1" range="-2.618 2.618"/>
              <geom type="mesh" class="visual" mesh="left_shoulder_yaw_link"/>
              <body name="left_elbow_pitch_link" pos="0 0.00189 -0.0855">
                <inertial pos="0.064497 0.002873 0" quat="0.582347 0.582495 0.400893 0.401069" mass="0.601"
                  diaginertia="0.00049549 0.0004712 0.00025371"/>
                <joint name="left_elbow_pitch_joint" axis="0 1 0" range="-0.2268 3.4208"/>
                <geom type="mesh" class="visual" mesh="left_elbow_pitch_link"/>
                <body name="left_elbow_roll_link" pos="0.1 0 0">
                  <inertial pos="0.133814 0.00147121 0.000265832" quat="0.496781 0.497877 0.498782 0.506502"
                    mass="0.50826" diaginertia="0.00239763 0.00226639 0.000285577"/>
                  <joint name="left_elbow_roll_joint" axis="1 0 0" range="-2.0943 2.0943"/>
                  <geom type="mesh" class="visual" mesh="left_elbow_roll_link"/>
                  <geom class="forearm_collision" />
                  <geom pos="0.15 0 0" type="sphere" size="0.03" class="visual" material="black"/>
                  <geom class="hand_collision"/>
                </body>
              </body>
            </body>
          </body>
        </body>
        <body name="right_shoulder_pitch_link" pos="-0.0025 -0.10396 0.25928" quat="0.990268 -0.139172 0 0">
          <inertial pos="-0.001431 -0.048811 0.001304" quat="0.588396 0.786417 -0.0523639 0.180543" mass="0.713"
            diaginertia="0.000466421 0.000440181 0.000410999"/>
          <joint name="right_shoulder_pitch_joint" axis="0 1 0" range="-2.9671 2.7925"/>
          <geom type="mesh" class="visual" mesh="right_shoulder_pitch_link"/>
          <body name="right_shoulder_roll_link" pos="0 -0.052 0" quat="0.990268 0.139172 0 0">
            <inertial pos="-0.003415 -0.006955 -0.064598" quat="0.707282 0.00575207 0.0105364 0.70683" mass="0.642"
              diaginertia="0.000683514 0.000616029 0.000372857"/>
            <joint name="right_shoulder_roll_joint" axis="1 0 0" range="-2.2515 1.5882"/>
            <geom type="mesh" class="visual" mesh="right_shoulder_roll_link"/>
            <geom class="shoulder_collision" />
            <body name="right_shoulder_yaw_link" pos="-0.00354 -0.0062424 -0.1032">
              <inertial pos="0.000375 0.00444 -0.072374" quat="0.42613 0.00985482 -0.0374183 0.903834" mass="0.713"
                diaginertia="0.000977874 0.000964661 0.000379065"/>
              <joint name="right_shoulder_yaw_joint" axis="0 0 1" range="-2.618 2.618"/>
              <geom type="mesh" class="visual" mesh="right_shoulder_yaw_link"/>
              <body name="right_elbow_pitch_link" pos="0 -0.00189 -0.0855">
                <inertial pos="0.064497 -0.002873 0" quat="0.401069 0.400893 0.582495 0.582347" mass="0.601"
                  diaginertia="0.00049549 0.0004712 0.00025371"/>
                <joint name="right_elbow_pitch_joint" axis="0 1 0" range="-0.2268 3.4208"/>
                <geom type="mesh" class="visual" mesh="right_elbow_pitch_link"/>
                <body name="right_elbow_roll_link" pos="0.1 0 0">
                  <inertial pos="0.133814 -0.00147121 0.000265832" quat="0.506502 0.498782 0.497877 0.496781"
                    mass="0.50826" diaginertia="0.00239763 0.00226639 0.000285577"/>
                  <joint name="right_elbow_roll_joint" axis="1 0 0" range="-2.0943 2.0943"/>
                  <geom type="mesh" class="visual" mesh="right_elbow_roll_link"/>
                  <geom class="forearm_collision" />
                  <geom pos="0.15 0 0" type="sphere" size="0.03" class="visual" material="black"/>
                  <geom class="hand_collision"/>
                </body>
              </body>
            </body>
          </body>
        </body>
      </body>
    </body>
  </worldbody>

  <actuator>
    <velocity class="hip_joint" name="left_hip_pitch_joint" joint="left_hip_pitch_joint"/>
    <velocity class="hip_joint" name="right_hip_pitch_joint" joint="right_hip_pitch_joint"/>
    <velocity class="hip_joint" name="left_hip_roll_joint" joint="left_hip_roll_joint"/>
    <velocity class="hip_joint" name="right_hip_roll_joint" joint="right_hip_roll_joint"/>
    <velocity class="hip_joint" name="right_hip_yaw_joint" joint="right_hip_yaw_joint"/>
    <velocity class="hip_joint" name="left_hip_yaw_joint" joint="left_hip_yaw_joint"/>

    <velocity class="knee_joint" name="left_knee_joint" joint="left_knee_joint"/>
    <velocity class="knee_joint" name="right_knee_joint" joint="right_knee_joint"/>

    <velocity class="ankle_joint" name="left_ankle_pitch_joint" joint="left_ankle_pitch_joint"/>
    <velocity class="ankle_joint" name="left_ankle_roll_joint" joint="left_ankle_roll_joint"/>
    <velocity class="ankle_joint" name="right_ankle_pitch_joint" joint="right_ankle_pitch_joint"/>
    <velocity class="ankle_joint" name="right_ankle_roll_joint" joint="right_ankle_roll_joint"/>

    <velocity class="torso_joint" name="torso_joint" joint="torso_joint"/>

    <velocity class="arm_joint" name="left_shoulder_pitch_joint" joint="left_shoulder_pitch_joint"/>
    <velocity class="arm_joint" name="left_shoulder_roll_joint" joint="left_shoulder_roll_joint"/>
    <velocity class="arm_joint" name="left_shoulder_yaw_joint" joint="left_shoulder_yaw_joint"/>
    <velocity class="arm_joint" name="left_elbow_pitch_joint" joint="left_elbow_pitch_joint"/>
    <velocity class="arm_joint" name="left_elbow_roll_joint" joint="left_elbow_roll_joint"/>

    <velocity class="arm_joint" name="right_shoulder_pitch_joint" joint="right_shoulder_pitch_joint"/>
    <velocity class="arm_joint" name="right_shoulder_roll_joint" joint="right_shoulder_roll_joint"/>
    <velocity class="arm_joint" name="right_shoulder_yaw_joint" joint="right_shoulder_yaw_joint"/>
    <velocity class="arm_joint" name="right_elbow_pitch_joint" joint="right_elbow_pitch_joint"/>
    <velocity class="arm_joint" name="right_elbow_roll_joint" joint="right_elbow_roll_joint"/>

  </actuator>

  <sensor>
    <gyro name="imu-angular-velocity" site="imu" cutoff="34.9"/>
    <accelerometer name="imu-linear-acceleration" site="imu" cutoff="157"/>
    <framequat name="imu-body-quat" objtype="site" objname="imu"/>
    <framelinvel name="imu-body-linvel" objtype="site" objname="imu"/>
    <subtreecom name="com" body="pelvis"/>
    <subtreelinvel name="com_vel" body="pelvis"/>
    <framepos name="left_heel" objtype="site" objname="left_heel"/>
    <framepos name="left_toe" objtype="site" objname="left_toe"/>
    <framepos name="right_heel" objtype="site" objname="right_heel"/>
    <framepos name="right_toe" objtype="site" objname="right_toe"/>
  </sensor>

  <keyframe>
    <key name="stand"
      qpos="
      0 0 0.75
      1 0 0 0
      0 0 0 0 0 0
      0 0 0 0 0 0
      0
      0 0 0 0 0
      0 0 0 0 0"/>
  </keyframe>
</mujoco>
