<mujoco model="pendulum">
  <!-- added manually -->
  <option timestep="0.02" iterations="1" ls_iterations="4">
    <flag contact="disable" eulerdamp="disable"/>
  </option>

  <worldbody>
    <body name="base" pos="0 0 1.5">
      <inertial pos="0 0 0" mass="2" diaginertia="0.00072 0.00072 0.00072"/>
      <geom name="base_visual" size="0.05 0.05 0.05" pos="0 0 0" type="box" />
      <body name="pendulum_link" pos="0 0 0">
        <inertial pos="0 0 -0.5" mass="1" diaginertia="0.087959 0.087959 0.00019896"/>
        <joint name="pendulum_joint" pos="0 0 0" axis="0 1 0" />
        <geom name="pendulum_link_visual" size="0.02 0.5" pos="0 0 -0.5" type="capsule" />
        <site name="tip" pos="0 0 -1"/>
      </body>
    </body>
  </worldbody>

  <actuator>
    <motor gear="2" name="pendulum_joint_actuator" ctrllimited="true" ctrlrange="-1.0 1.0" joint="pendulum_joint"/>
  </actuator>
  <equality/>
</mujoco>
