<mujoco model="pusht">
  <option timestep="0.01" iterations="1" ls_iterations="4" />

  <default>
    <position ctrllimited="true" ctrlrange="-0.3 0.3" kp="1.0" dampratio="1.0"/>
    <velocity ctrllimited="true" ctrlrange="-0.5 0.5" kv="0.1"/>
    <default class="goal">
      <geom conaffinity="0" contype="0" rgba="0 1 0 0.2"/>
    </default>
    <geom friction="1.0" solimp="0.0 0.95 0.005" solref="0.02 1"/>
  </default>

  <worldbody>
    <body name="goal" mocap="true" pos="0.0 0.0 0.01">
      <geom class="goal" name="goal_bottom" type="box" size=".01 0.04 0.01"/>
      <geom class="goal" name="goal_top" type="box" size=".03 0.01 0.01" pos="0.0 0.03 0.0"/>
    </body>

    <body name="block" pos="0.0 0.0 0.0095">
      <joint name="T_x" type="slide" pos="0 0 0" axis="1 0 0" />
      <joint name="T_y" type="slide" pos="0 0 0" axis="0 1 0" />
      <joint name="T_z" axis="0 0 1"/>
      <geom name="bottom" type="box" size=".01 0.04 0.01" />
      <geom name="top" type="box" size=".03 0.01 0.01" pos="0.0 0.03 0.0" />
    </body>

    <body name="pusher" pos="0 .1 .011">
      <joint name="root_x" type="slide" pos="0 0 0" axis="1 0 0" />
      <joint name="root_y" type="slide" pos="0 0 0" axis="0 1 0" />
      <geom name="pusher" type="sphere" size=".01" rgba="1 0 0 1" />
      <site name="pusher" pos="0 0 0" rgba="0 0 0 0"/>
    </body>
  </worldbody>

  <actuator>
    <velocity name="x_motor" joint="root_x" />
    <velocity name="y_motor" joint="root_y" />
  </actuator>

  <sensor>
    <framepos name="position" objtype="body" objname="block" reftype="body" refname="goal"/>
    <framequat name="orientation" objtype="body" objname="block" reftype="body" refname="goal"/>
  </sensor>
</mujoco>
