<mujoco model="walker">
  <!-- Adopted from the MJPC walker task
   https://github.com/google-deepmind/mujoco_mpc/tree/main/mjpc/tasks/walker``
   -->
  <option timestep="0.01" iterations="1" ls_iterations="6">
    <flag eulerdamp="disable"/>
  </option>

  <custom>
    <numeric data="5" name="max_contact_points"/>
    <numeric data="5" name="max_geom_pairs"/>
  </custom>

  <default>
    <joint damping=".1" armature="0.01" limited="true" />
    <geom contype="1" conaffinity="0" friction=".5" solref="0.02 1.0" solimp="0.0 0.95 0.01"/>
    <motor ctrlrange="-1 1" ctrllimited="true"/>
    <site size="0.01"/>
    <default class="walker">
      <geom type="capsule"/>
      <joint axis="0 -1 0"/>
    </default>
  </default>

  <worldbody>
    <body name="torso" pos="0 0 1.3" childclass="walker">
      <light name="light" pos="0 0 2" mode="trackcom"/>
      <camera name="floating"  pos="0 -2 0" xyaxes="1 0 0 0 0 1" mode="trackcom" fovy="90"/>
      <joint name="rootz" axis="0 0 1" type="slide" limited="false" armature="0" damping="0"/>
      <joint name="rootx" axis="1 0 0" type="slide" limited="false" armature="0" damping="0"/>
      <joint name="rooty" axis="0 1 0" type="hinge" limited="false" armature="0" damping="0"/>
      <geom name="torso" size="0.07 0.3"/>
      <site name="torso_site" pos="0 0 0" size="0.01"/>
      <body name="right_thigh" pos="0 -.05 -0.3">
        <joint name="right_hip" range="-20 100"/>
        <geom name="right_thigh" pos="0 0 -0.225" size="0.05 0.225"/>
        <body name="right_leg" pos="0 0 -0.7">
          <joint name="right_knee" pos="0 0 0.25" range="-150 0"/>
          <geom name="right_leg" size="0.04 0.25"/>
          <body name="right_foot" pos="0.06 0 -0.25">
            <joint name="right_ankle" pos="-0.06 0 0" range="-45 45"/>
            <geom name="right_foot" zaxis="1 0 0" size="0.05 0.1"/>
            <site name="right_foot_site" pos="0 0 0" size="0.01"/>
          </body>
        </body>
      </body>
      <body name="left_thigh" pos="0 .05 -0.3" >
        <joint name="left_hip" range="-20 100"/>
        <geom name="left_thigh" pos="0 0 -0.225" size="0.05 0.225"/>
        <body name="left_leg" pos="0 0 -0.7">
          <joint name="left_knee" pos="0 0 0.25" range="-150 0"/>
          <geom name="left_leg" size="0.04 0.25"/>
          <body name="left_foot" pos="0.06 0 -0.25">
            <joint name="left_ankle" pos="-0.06 0 0" range="-45 45"/>
            <geom name="left_foot" zaxis="1 0 0" size="0.05 0.1"/>
            <site name="left_foot_site" pos="0 0 0" size="0.01"/>
          </body>
        </body>
      </body>
    </body>
  </worldbody>

  <sensor>
    <framepos      name="torso_position" objtype="xbody" objname="torso"/>
    <subtreelinvel name="torso_subtreelinvel" body="torso"/>
    <framezaxis    name="torso_zaxis" objtype="xbody" objname="torso"/>
  </sensor>

  <actuator>
    <motor name="right_hip" joint="right_hip" gear="100"/>
    <motor name="right_knee" joint="right_knee" gear="50"/>
    <motor name="right_ankle" joint="right_ankle" gear="20"/>
    <motor name="left_hip" joint="left_hip" gear="100"/>
    <motor name="left_knee" joint="left_knee" gear="50"/>
    <motor name="left_ankle" joint="left_ankle" gear="20"/>
  </actuator>
</mujoco>
